<?xml version="1.0" encoding="UTF-8"?>
<testng-results skipped="0" failed="2" total="2" passed="0">
  <reporter-output>
  </reporter-output>
  <suite name="Default suite" duration-ms="54" started-at="2018-12-01T17:52:06Z" finished-at="2018-12-01T17:52:06Z">
    <groups>
    </groups>
    <test name="Default test" duration-ms="54" started-at="2018-12-01T17:52:06Z" finished-at="2018-12-01T17:52:06Z">
      <class name="com.epam.training.triangle.CheckGetSquareNegativeTest">
        <test-method status="FAIL" signature="tstGetSquareCheckDoubleValue()[pri:0, instance:com.epam.training.triangle.CheckGetSquareNegativeTest@137cf78]" name="tstGetSquareCheckDoubleValue" duration-ms="16" started-at="2018-12-01T17:52:06Z" finished-at="2018-12-01T17:52:06Z">
          <exception class="org.testng.TestException">
            <message>
              <![CDATA[
Expected exception java.lang.Exception but got org.testng.TestException: 
Method CheckGetSquareNegativeTest.tstGetSquareCheckDoubleValue()[pri:0, instance:com.epam.training.triangle.CheckGetSquareNegativeTest@137cf78] should have thrown an exception of class java.lang.Exception]]>
            </message>
            <full-stacktrace>
              <![CDATA[org.testng.TestException: 
Expected exception java.lang.Exception but got org.testng.TestException: 
Method CheckGetSquareNegativeTest.tstGetSquareCheckDoubleValue()[pri:0, instance:com.epam.training.triangle.CheckGetSquareNegativeTest@137cf78] should have thrown an exception of class java.lang.Exception
	at org.testng.internal.Invoker.handleInvocationResults(Invoker.java:1485)
	at org.testng.internal.Invoker.invokeTestMethods(Invoker.java:1233)
	at org.testng.internal.TestMethodWorker.invokeTestMethods(TestMethodWorker.java:127)
	at org.testng.internal.TestMethodWorker.run(TestMethodWorker.java:111)
	at org.testng.TestRunner.privateRun(TestRunner.java:768)
	at org.testng.TestRunner.run(TestRunner.java:617)
	at org.testng.SuiteRunner.runTest(SuiteRunner.java:334)
	at org.testng.SuiteRunner.runSequentially(SuiteRunner.java:329)
	at org.testng.SuiteRunner.privateRun(SuiteRunner.java:291)
	at org.testng.SuiteRunner.run(SuiteRunner.java:240)
	at org.testng.SuiteRunnerWorker.runSuite(SuiteRunnerWorker.java:53)
	at org.testng.SuiteRunnerWorker.run(SuiteRunnerWorker.java:87)
	at org.testng.TestNG.runSuitesSequentially(TestNG.java:1188)
	at org.testng.TestNG.runSuitesLocally(TestNG.java:1113)
	at org.testng.TestNG.run(TestNG.java:1025)
	at org.testng.remote.AbstractRemoteTestNG.run(AbstractRemoteTestNG.java:114)
	at org.testng.remote.RemoteTestNG.initAndRun(RemoteTestNG.java:251)
	at org.testng.remote.RemoteTestNG.main(RemoteTestNG.java:77)
Caused by: org.testng.TestException: 
Method CheckGetSquareNegativeTest.tstGetSquareCheckDoubleValue()[pri:0, instance:com.epam.training.triangle.CheckGetSquareNegativeTest@137cf78] should have thrown an exception of class java.lang.Exception
	at org.testng.internal.Invoker.handleInvocationResults(Invoker.java:1500)
	at org.testng.internal.Invoker.invokeMethod(Invoker.java:751)
	at org.testng.internal.Invoker.invokeTestMethod(Invoker.java:894)
	at org.testng.internal.Invoker.invokeTestMethods(Invoker.java:1219)
	... 16 more
]]>
            </full-stacktrace>
          </exception> <!-- org.testng.TestException -->
        </test-method> <!-- tstGetSquareCheckDoubleValue -->
        <test-method status="FAIL" signature="tstGetSquareCheckMaxDoubleValue()[pri:0, instance:com.epam.training.triangle.CheckGetSquareNegativeTest@137cf78]" name="tstGetSquareCheckMaxDoubleValue" duration-ms="0" started-at="2018-12-01T17:52:06Z" finished-at="2018-12-01T17:52:06Z">
          <exception class="org.testng.TestException">
            <message>
              <![CDATA[
Expected exception java.lang.Exception but got org.testng.TestException: 
Method CheckGetSquareNegativeTest.tstGetSquareCheckMaxDoubleValue()[pri:0, instance:com.epam.training.triangle.CheckGetSquareNegativeTest@137cf78] should have thrown an exception of class java.lang.Exception]]>
            </message>
            <full-stacktrace>
              <![CDATA[org.testng.TestException: 
Expected exception java.lang.Exception but got org.testng.TestException: 
Method CheckGetSquareNegativeTest.tstGetSquareCheckMaxDoubleValue()[pri:0, instance:com.epam.training.triangle.CheckGetSquareNegativeTest@137cf78] should have thrown an exception of class java.lang.Exception
	at org.testng.internal.Invoker.handleInvocationResults(Invoker.java:1485)
	at org.testng.internal.Invoker.invokeTestMethods(Invoker.java:1233)
	at org.testng.internal.TestMethodWorker.invokeTestMethods(TestMethodWorker.java:127)
	at org.testng.internal.TestMethodWorker.run(TestMethodWorker.java:111)
	at org.testng.TestRunner.privateRun(TestRunner.java:768)
	at org.testng.TestRunner.run(TestRunner.java:617)
	at org.testng.SuiteRunner.runTest(SuiteRunner.java:334)
	at org.testng.SuiteRunner.runSequentially(SuiteRunner.java:329)
	at org.testng.SuiteRunner.privateRun(SuiteRunner.java:291)
	at org.testng.SuiteRunner.run(SuiteRunner.java:240)
	at org.testng.SuiteRunnerWorker.runSuite(SuiteRunnerWorker.java:53)
	at org.testng.SuiteRunnerWorker.run(SuiteRunnerWorker.java:87)
	at org.testng.TestNG.runSuitesSequentially(TestNG.java:1188)
	at org.testng.TestNG.runSuitesLocally(TestNG.java:1113)
	at org.testng.TestNG.run(TestNG.java:1025)
	at org.testng.remote.AbstractRemoteTestNG.run(AbstractRemoteTestNG.java:114)
	at org.testng.remote.RemoteTestNG.initAndRun(RemoteTestNG.java:251)
	at org.testng.remote.RemoteTestNG.main(RemoteTestNG.java:77)
Caused by: org.testng.TestException: 
Method CheckGetSquareNegativeTest.tstGetSquareCheckMaxDoubleValue()[pri:0, instance:com.epam.training.triangle.CheckGetSquareNegativeTest@137cf78] should have thrown an exception of class java.lang.Exception
	at org.testng.internal.Invoker.handleInvocationResults(Invoker.java:1500)
	at org.testng.internal.Invoker.invokeMethod(Invoker.java:751)
	at org.testng.internal.Invoker.invokeTestMethod(Invoker.java:894)
	at org.testng.internal.Invoker.invokeTestMethods(Invoker.java:1219)
	... 16 more
]]>
            </full-stacktrace>
          </exception> <!-- org.testng.TestException -->
        </test-method> <!-- tstGetSquareCheckMaxDoubleValue -->
      </class> <!-- com.epam.training.triangle.CheckGetSquareNegativeTest -->
    </test> <!-- Default test -->
  </suite> <!-- Default suite -->
</testng-results>
