<?xml version="1.0" encoding="UTF-8"?>
<!-- Generated by org.testng.reporters.JUnitReportReporter -->
<testsuite hostname="Daria-PC" name="com.epam.training.triangle.CheckGetSquareNegativeTest" tests="2" failures="2" timestamp="1 Dec 2018 14:52:06 GMT" time="0.016" errors="0">
  <testcase name="tstGetSquareCheckMaxDoubleValue" time="0.000" classname="com.epam.training.triangle.CheckGetSquareNegativeTest">
    <failure type="org.testng.TestException" message="
Expected exception java.lang.Exception but got org.testng.TestException: 
Method CheckGetSquareNegativeTest.tstGetSquareCheckMaxDoubleValue()[pri:0, instance:com.epam.training.triangle.CheckGetSquareNegativeTest@137cf78] should have thrown an exception of class java.lang.Exception">
      <![CDATA[org.testng.TestException: 
Expected exception java.lang.Exception but got org.testng.TestException: 
Method CheckGetSquareNegativeTest.tstGetSquareCheckMaxDoubleValue()[pri:0, instance:com.epam.training.triangle.CheckGetSquareNegativeTest@137cf78] should have thrown an exception of class java.lang.Exception
	at org.testng.internal.Invoker.handleInvocationResults(Invoker.java:1485)
	at org.testng.internal.Invoker.invokeTestMethods(Invoker.java:1233)
	at org.testng.internal.TestMethodWorker.invokeTestMethods(TestMethodWorker.java:127)
	at org.testng.internal.TestMethodWorker.run(TestMethodWorker.java:111)
	at org.testng.TestRunner.privateRun(TestRunner.java:768)
	at org.testng.TestRunner.run(TestRunner.java:617)
	at org.testng.SuiteRunner.runTest(SuiteRunner.java:334)
	at org.testng.SuiteRunner.runSequentially(SuiteRunner.java:329)
	at org.testng.SuiteRunner.privateRun(SuiteRunner.java:291)
	at org.testng.SuiteRunner.run(SuiteRunner.java:240)
	at org.testng.SuiteRunnerWorker.runSuite(SuiteRunnerWorker.java:53)
	at org.testng.SuiteRunnerWorker.run(SuiteRunnerWorker.java:87)
	at org.testng.TestNG.runSuitesSequentially(TestNG.java:1188)
	at org.testng.TestNG.runSuitesLocally(TestNG.java:1113)
	at org.testng.TestNG.run(TestNG.java:1025)
	at org.testng.remote.AbstractRemoteTestNG.run(AbstractRemoteTestNG.java:114)
	at org.testng.remote.RemoteTestNG.initAndRun(RemoteTestNG.java:251)
	at org.testng.remote.RemoteTestNG.main(RemoteTestNG.java:77)
Caused by: org.testng.TestException: 
Method CheckGetSquareNegativeTest.tstGetSquareCheckMaxDoubleValue()[pri:0, instance:com.epam.training.triangle.CheckGetSquareNegativeTest@137cf78] should have thrown an exception of class java.lang.Exception
	at org.testng.internal.Invoker.handleInvocationResults(Invoker.java:1500)
	at org.testng.internal.Invoker.invokeMethod(Invoker.java:751)
	at org.testng.internal.Invoker.invokeTestMethod(Invoker.java:894)
	at org.testng.internal.Invoker.invokeTestMethods(Invoker.java:1219)
	... 16 more
]]>
    </failure>
  </testcase> <!-- tstGetSquareCheckMaxDoubleValue -->
  <testcase name="tstGetSquareCheckDoubleValue" time="0.016" classname="com.epam.training.triangle.CheckGetSquareNegativeTest">
    <failure type="org.testng.TestException" message="
Expected exception java.lang.Exception but got org.testng.TestException: 
Method CheckGetSquareNegativeTest.tstGetSquareCheckDoubleValue()[pri:0, instance:com.epam.training.triangle.CheckGetSquareNegativeTest@137cf78] should have thrown an exception of class java.lang.Exception">
      <![CDATA[org.testng.TestException: 
Expected exception java.lang.Exception but got org.testng.TestException: 
Method CheckGetSquareNegativeTest.tstGetSquareCheckDoubleValue()[pri:0, instance:com.epam.training.triangle.CheckGetSquareNegativeTest@137cf78] should have thrown an exception of class java.lang.Exception
	at org.testng.internal.Invoker.handleInvocationResults(Invoker.java:1485)
	at org.testng.internal.Invoker.invokeTestMethods(Invoker.java:1233)
	at org.testng.internal.TestMethodWorker.invokeTestMethods(TestMethodWorker.java:127)
	at org.testng.internal.TestMethodWorker.run(TestMethodWorker.java:111)
	at org.testng.TestRunner.privateRun(TestRunner.java:768)
	at org.testng.TestRunner.run(TestRunner.java:617)
	at org.testng.SuiteRunner.runTest(SuiteRunner.java:334)
	at org.testng.SuiteRunner.runSequentially(SuiteRunner.java:329)
	at org.testng.SuiteRunner.privateRun(SuiteRunner.java:291)
	at org.testng.SuiteRunner.run(SuiteRunner.java:240)
	at org.testng.SuiteRunnerWorker.runSuite(SuiteRunnerWorker.java:53)
	at org.testng.SuiteRunnerWorker.run(SuiteRunnerWorker.java:87)
	at org.testng.TestNG.runSuitesSequentially(TestNG.java:1188)
	at org.testng.TestNG.runSuitesLocally(TestNG.java:1113)
	at org.testng.TestNG.run(TestNG.java:1025)
	at org.testng.remote.AbstractRemoteTestNG.run(AbstractRemoteTestNG.java:114)
	at org.testng.remote.RemoteTestNG.initAndRun(RemoteTestNG.java:251)
	at org.testng.remote.RemoteTestNG.main(RemoteTestNG.java:77)
Caused by: org.testng.TestException: 
Method CheckGetSquareNegativeTest.tstGetSquareCheckDoubleValue()[pri:0, instance:com.epam.training.triangle.CheckGetSquareNegativeTest@137cf78] should have thrown an exception of class java.lang.Exception
	at org.testng.internal.Invoker.handleInvocationResults(Invoker.java:1500)
	at org.testng.internal.Invoker.invokeMethod(Invoker.java:751)
	at org.testng.internal.Invoker.invokeTestMethod(Invoker.java:894)
	at org.testng.internal.Invoker.invokeTestMethods(Invoker.java:1219)
	... 16 more
]]>
    </failure>
  </testcase> <!-- tstGetSquareCheckDoubleValue -->
</testsuite> <!-- com.epam.training.triangle.CheckGetSquareNegativeTest -->
